<?xml version="1.0"?>
<robot xmlns:xacro="http://www.ros.org/wiki/xacro">
    <xacro:macro name="link_wheel" params="name">
        <link name="${name}">
            <inertial>
              <mass value="2.5"/>
              <origin rpy="0 ${M_PI/2} ${M_PI/2}" xyz="0 0 0"/>
              <inertia  ixx="0.02467" ixy="0" ixz="0" iyy="0.04411" iyz="0" izz="0.02467" />
            </inertial>
            <collision name="link_right_wheel_collision">
              <origin rpy="0 ${M_PI/2} ${M_PI/2}" xyz="0 0 0"/>
              <geometry>
                <cylinder length="0.03" radius="0.1"/>
              </geometry>
            </collision>
            <visual name="${name}_visual">
              <origin rpy="0 ${M_PI/2} ${M_PI/2}" xyz="0 0 0"/>
              <geometry>
                <cylinder length="0.03" radius="0.1"/>
              </geometry>
            </visual>
        </link>
    </xacro:macro>

    <xacro:macro name="joint_wheel" params="name child origin_xyz">
      <joint name="${name}" type="continuous">
        <origin rpy="0 0 0" xyz="${origin_xyz}"/>
        <child link="${child}"/>
        <parent link="base_link"/>
        <axis rpy="0 0 0" xyz="0 1 0"/>
        <limit effort="10000" velocity="1000"/>
        <joint_properties damping="1.0" friction="1.0"/>
      </joint>
    </xacro:macro>

</robot>
